Workbook

Sheet Control_Panel
A1: Control Panel
A2: Application entry point. Button cells identify macro actions after VBA import.
A4: Action | B4: Macro / Target | C4: Status / Notes
A5: Refresh All | B5: RefreshAll | C5: Rebuilds register, buildup, cash flow, escalation, contingency, dashboard and QA
A6: Build Cost Register | B6: BuildCostRegister | C6: Header-based macro; reads input sheets only
A7: Run QA | B7: RunQA | C7: Writes PASS/FAIL to QA_Checks
A8: Run Monte Carlo | B8: RunMonteCarlo | C8: Populates MonteCarlo_Results only; does not touch charts
A9: Load Demo Project | B9: LoadDemoProject | C9: Reloads 40 M€ demo dataset
A10: Reset Demo Data | B10: ResetDemoData | C10: Clears demo input/output areas
A11: Last Refresh | C11: 2026-06-03 14:03:33
A12: Last QA Status | C12: =NOW()
A13: Cost Items | C13: =MAX(0,COUNTA(Cost_Register!$C$5:$C$500))
A14: Base Cost EUR | C14: =SUM(Cost_Register!$P$5:$P$500)
A15: Total Project Cost EUR | C15: ='Estimate_Summary'!B18
A17: Key sheet | B17: Purpose
A18: Project_Setup | B18: Project metadata and defaults
A19: Cost_Register | B19: Single source of truth
A20: Estimate_Summary | B20: Executive output
A21: Dashboard | B21: Charts and KPI overview
A22: QA_Checks | B22: Gate status
A23: ReadMe | B23: Use instructions
A24: Release_Notes | B24: Limitations and next steps
A25: VBA source | B25: See exported .bas file
A27: Configurable Parameter | B27: Source / Macro Use | C27: Value
A28: Data Mode | B28: LoadDemoProject / ResetDemoData | C28: ='Project_Setup'!B18
A29: Monte Carlo Iterations | B29: RunMonteCarlo | C29: ='Project_Setup'!B19
A30: Standard Hours per Month | B30: Resource_Rates / Manpower | C30: ='Project_Setup'!B20
A31: Project Duration Months | B31: CashFlow / Manpower / Charts | C31: ='Project_Setup'!B12
A32: Annual Escalation Rate | B32: CalculateCashFlow / CalculateEscalation | C32: ='Project_Setup'!B15
A33: Selected Contingency Method | B33: CalculateContingency | C33: ='Project_Setup'!B14
A34: Release Package | B34: Workbook is xlsx; VBA provided as .bas for import into Excel | C34: See Release_Notes
A35: Final Status | B35: Automated tests performed in artifact environment | C35: Candidate - Excel desktop VBA import required

Sheet Project_Setup
A1: Project Setup
A2: Primary project metadata and global defaults.
A4: Project Name | B4: Industrial CAPEX Demo Project - Clean Build RC8
A5: Project Code | B5: CAPEX-RC8-DEMO
A6: Estimate Date | B6: 46176
A7: Estimate Class | B7: Class 3
A8: Project Phase | B8: FEED
A9: Base Currency | B9: EUR
A10: Project Start Date | B10: 46204
A11: Project End Date | B11: 47299
A12: Project Duration Months | B12: =(YEAR(B11)-YEAR(B10))*12+MONTH(B11)-MONTH(B10)+1
A13: Base Cost Target EUR | B13: 40000000
A14: Default Contingency Method | B14: Monte Carlo P80 - Base Cost
A15: Default Annual Escalation | B15: 0.03
A16: Excel Target | B16: Microsoft Excel desktop Windows
A17: Build Rule | B17: Clean rebuild from functional references only
A18: Data Mode | B18: Demo
A19: Monte Carlo Iterations | B19: 10000
A20: Standard Hours per Month | B20: 160
A21: Max Cash Flow Months | B21: 60
A22: RC8.1 Status | B22: Patched workbook + corrected VBA module supplied separately

Sheet Basis_of_Estimate
A1: Basis of Estimate
A2: Configurable AACE-style estimate classes and accuracy ranges.
A4: Estimate Class | B4: Description | C4: Low Accuracy % | D4: High Accuracy % | E4: Typical Deliverables | F4: Configurable | G4: Default Contingency Range | H4: Notes
A5: Class 5 | B5: Concept Screening | C5: -0.5 | D5: 1 | E5: Stage gate package, scope definition, quantity maturity, vendor inputs | F5: Yes | G5: 10%–25% | H5: Used by all input sheets
A6: Class 4 | B6: Concept Selection | C6: -0.3 | D6: 0.5 | E6: Stage gate package, scope definition, quantity maturity, vendor inputs | F6: Yes | G6: 10%–25% | H6: Used by all input sheets
A7: Class 3 | B7: FEED | C7: -0.2 | D7: 0.3 | E7: Stage gate package, scope definition, quantity maturity, vendor inputs | F7: Yes | G7: 8%–15% | H7: Used by all input sheets
A8: Class 2 | B8: Pre-Execution | C8: -0.15 | D8: 0.2 | E8: Stage gate package, scope definition, quantity maturity, vendor inputs | F8: Yes | G8: 8%–15% | H8: Used by all input sheets
A9: Class 1 | B9: Definitive Estimate | C9: -0.1 | D9: 0.15 | E9: Stage gate package, scope definition, quantity maturity, vendor inputs | F9: Yes | G9: 8%–15% | H9: Used by all input sheets

Sheet WBS_CBS
A1: WBS / CBS
A2: Standard breakdown structure used across Cost_Register and reports.
A4: WBS | B4: WBS Description | C4: CBS | D4: CBS Description | E4: Default Discipline | F4: Default Phase | G4: WBS Display | H4: Active | I4: Notes | J4: Default Cost Category | K4: Default Spend Category | L4: Default Spend Curve | M4: Default Contingency Eligible | N4: Default Escalation Eligible
A5: 1.0 | B5: Project Management | C5: PM | D5: Project Management | E5: Project Management | F5: Engineering | G5: 1.0 - Project Management | H5: Yes | I5: Clean build standard list | J5: Indirect Cost | K5: Engineering | L5: Bell Curve | M5: Yes | N5: Yes
A6: 2.0 | B6: Engineering | C6: ENG | D6: Engineering | E6: Project Management | F6: Engineering | G6: 2.0 - Engineering | H6: Yes | I6: Clean build standard list | J6: Indirect Cost | K6: Engineering | L6: Bell Curve | M6: Yes | N6: Yes
A7: 3.0 | B7: Procurement | C7: PROC | D7: Procurement | E7: Procurement | F7: Procurement | G7: 3.0 - Procurement | H7: Yes | I7: Clean build standard list | J7: Indirect Cost | K7: Procurement | L7: Linear | M7: Yes | N7: Yes
A8: 4.0 | B8: Equipment | C8: EQP | D8: Equipment | E8: Mechanical | F8: Procurement | G8: 4.0 - Equipment | H8: Yes | I8: Clean build standard list | J8: Direct Cost | K8: Procurement | L8: Back Loaded | M8: Yes | N8: Yes
A9: 5.0 | B9: Bulk Materials | C9: BULK | D9: Bulk Materials | E9: Piping | F9: Procurement | G9: 5.0 - Bulk Materials | H9: Yes | I9: Clean build standard list | J9: Direct Cost | K9: Procurement | L9: Linear | M9: Yes | N9: Yes
A10: 6.0 | B10: Civil & Structural | C10: CIV | D10: Civil | E10: Civil | F10: Construction | G10: 6.0 - Civil & Structural | H10: Yes | I10: Clean build standard list | J10: Direct Cost | K10: Construction | L10: Front Loaded | M10: Yes | N10: Yes
A11: 7.0 | B11: Electrical | C11: ELE | D11: Electrical | E11: Electrical | F11: Construction | G11: 7.0 - Electrical | H11: Yes | I11: Clean build standard list | J11: Direct Cost | K11: Construction | L11: Bell Curve | M11: Yes | N11: Yes
A12: 8.0 | B12: Instrumentation & Automation | C12: I&A | D12: Instrumentation & Automation | E12: Instrumentation | F12: Construction | G12: 8.0 - Instrumentation & Automation | H12: Yes | I12: Clean build standard list | J12: Direct Cost | K12: Construction | L12: Bell Curve | M12: Yes | N12: Yes
A13: 9.0 | B13: Construction | C13: CON | D13: Construction | E13: Construction | F13: Construction | G13: 9.0 - Construction | H13: Yes | I13: Clean build standard list | J13: Direct Cost | K13: Construction | L13: Bell Curve | M13: Yes | N13: Yes
A14: 10.0 | B14: Commissioning & Start-up | C14: COM | D14: Commissioning | E14: Commissioning | F14: Commissioning | G14: 10.0 - Commissioning & Start-up | H14: Yes | I14: Clean build standard list | J14: Direct Cost | K14: Commissioning | L14: Back Loaded | M14: Yes | N14: Yes
A15: 11.0 | B15: Owner Costs | C15: OWN | D15: Owner Costs | E15: Owner | F15: Other | G15: 11.0 - Owner Costs | H15: Yes | I15: Clean build standard list | J15: Owner Cost | K15: Other | L15: Front Loaded | M15: Yes | N15: Yes
A16: 12.0 | B16: Other Costs | C16: OTH | D16: Other Costs | E16: Other | F16: Other | G16: 12.0 - Other Costs | H16: Yes | I16: Clean build standard list | J16: Other Cost | K16: Other | L16: Back Loaded | M16: Yes | N16: Yes

Sheet FX_Rates
A1: FX Rates
A2: Configurable rate to EUR. EUR is the base currency.
A4: Currency | B4: Rate to EUR | C4: Source / Notes | D4: Last Updated | E4: Active | F4: QA
A5: EUR | B5: 1 | C5: Demo static rate. Replace with approved project FX. | D5: 46176 | E5: Yes | F5: PASS
A6: USD | B6: 0.92 | C6: Demo static rate. Replace with approved project FX. | D6: 46176 | E6: Yes | F6: PASS
A7: GBP | B7: 1.17 | C7: Demo static rate. Replace with approved project FX. | D7: 46176 | E7: Yes | F7: PASS
A8: CHF | B8: 1.04 | C8: Demo static rate. Replace with approved project FX. | D8: 46176 | E8: Yes | F8: PASS
A9: DKK | B9: 0.134 | C9: Demo static rate. Replace with approved project FX. | D9: 46176 | E9: Yes | F9: PASS
A10: SEK | B10: 0.087 | C10: Demo static rate. Replace with approved project FX. | D10: 46176 | E10: Yes | F10: PASS
A11: NOK | B11: 0.086 | C11: Demo static rate. Replace with approved project FX. | D11: 46176 | E11: Yes | F11: PASS
A12: PLN | B12: 0.235 | C12: Demo static rate. Replace with approved project FX. | D12: 46176 | E12: Yes | F12: PASS
A13: TRY | B13: 0.028 | C13: Demo static rate. Replace with approved project FX. | D13: 46176 | E13: Yes | F13: PASS
A14: MAD | B14: 0.092 | C14: Demo static rate. Replace with approved project FX. | D14: 46176 | E14: Yes | F14: PASS

Sheet Lists_Config
A1: Lists Config
A2: Central dropdown values. Input sheets use these lists.
A4: Discipline | B4: Cost Category | C4: Cost Type | D4: Phase | E4: Y/N | F4: Currency | G4: Estimate Basis | H4: Spend Category | I4: Spend Curve | J4: Unit | K4: Location
A5: Process | B5: Direct Cost | C5: Equipment | D5: Engineering | E5: Yes | F5: EUR | G5: Class 5 | H5: Engineering | I5: Linear | J5: lot | K5: Spain
A6: Mechanical | B6: Indirect Cost | C6: Bulk Material | D6: Procurement | E6: No | F6: USD | G6: Class 4 | H6: Procurement | I6: Front Loaded | J6: each | K6: France
A7: Piping | B7: Owner Cost | C7: Construction | D7: Construction | F7: GBP | G7: Class 3 | H7: Construction | I7: Back Loaded | J7: m | K7: Germany
A8: Civil | B8: Manpower Cost | C8: Engineering | D8: Commissioning | F8: CHF | G8: Class 2 | H8: Commissioning | I8: Bell Curve | J8: m2 | K8: Italy
A9: Electrical | B9: Other Cost | C9: EPCM | D9: Other | F9: DKK | G9: Class 1 | H9: Other | I9: Manual | J9: m3 | K9: Netherlands
A10: Instrumentation | C10: Owner | F10: SEK | J10: kg | K10: Belgium
A11: Automation | C11: Labour | F11: NOK | J11: ton | K11: UK
A12: Construction | C12: Freight | F12: PLN | J12: h | K12: Poland
A13: Project Management | C13: Spares | F13: TRY | J13: month | K13: Remote
A14: Procurement | C14: Other | F14: MAD | J14: FTE-month
A15: HSE
A16: Commissioning
A17: Owner
A18: Other

Sheet Data_Dictionary
A1: Data Dictionary
A2: Column-level definition of operational sheets.
A4: Sheet | B4: Column | C4: Description | D4: Type | E4: Required | F4: Input / Formula / Macro | G4: Source | H4: Validation | I4: Used By | J4: Notes
A5: Equipment_Estimate | B5: Item ID | C5: Item ID for elementary cost item | D5: Text/Number | E5: Yes | F5: Input | G5: User / Config | H5: Lists_Config / formula | I5: BuildCostRegister, QA, Summary | J5: Header-based mapping required
A6: Equipment_Estimate | B6: Description | C6: Description for elementary cost item | D6: Text/Number | E6: Yes | F6: Input | G6: User / Config | H6: Lists_Config / formula | I6: BuildCostRegister, QA, Summary | J6: Header-based mapping required
A7: Equipment_Estimate | B7: Discipline | C7: Discipline for elementary cost item | D7: Text/Number | E7: Yes | F7: Input | G7: User / Config | H7: Lists_Config / formula | I7: BuildCostRegister, QA, Summary | J7: Header-based mapping required
A8: Equipment_Estimate | B8: WBS | C8: WBS for elementary cost item | D8: Text/Number | E8: Yes | F8: Input | G8: User / Config | H8: Lists_Config / formula | I8: BuildCostRegister, QA, Summary | J8: Header-based mapping required
A9: Equipment_Estimate | B9: CBS | C9: CBS for elementary cost item | D9: Text/Number | E9: Yes | F9: Input | G9: User / Config | H9: Lists_Config / formula | I9: BuildCostRegister, QA, Summary | J9: Header-based mapping required
A10: Equipment_Estimate | B10: Cost Category | C10: Cost Category for elementary cost item | D10: Text/Number | E10: Yes | F10: Input | G10: User / Config | H10: Lists_Config / formula | I10: BuildCostRegister, QA, Summary | J10: Header-based mapping required
A11: Equipment_Estimate | B11: Cost Type | C11: Cost Type for elementary cost item | D11: Text/Number | E11: Yes | F11: Input | G11: User / Config | H11: Lists_Config / formula | I11: BuildCostRegister, QA, Summary | J11: Header-based mapping required
A12: Equipment_Estimate | B12: Quantity | C12: Quantity for elementary cost item | D12: Text/Number | E12: Yes | F12: Input | G12: User / Config | H12: Lists_Config / formula | I12: BuildCostRegister, QA, Summary | J12: Header-based mapping required
A13: Equipment_Estimate | B13: Unit | C13: Unit for elementary cost item | D13: Text/Number | E13: Yes | F13: Input | G13: User / Config | H13: Lists_Config / formula | I13: BuildCostRegister, QA, Summary | J13: Header-based mapping required
A14: Equipment_Estimate | B14: Unit Rate | C14: Unit Rate for elementary cost item | D14: Text/Number | E14: Yes | F14: Input | G14: User / Config | H14: Lists_Config / formula | I14: BuildCostRegister, QA, Summary | J14: Header-based mapping required
A15: Equipment_Estimate | B15: Currency | C15: Currency for elementary cost item | D15: Text/Number | E15: Yes | F15: Input | G15: User / Config | H15: Lists_Config / formula | I15: BuildCostRegister, QA, Summary | J15: Header-based mapping required
... A200: Other_Costs | B200: Notes | C200: Notes for elementary cost item | D200: Text/Number | E200: No | F200: Input | G200: User / Config | H200: Lists_Config / formula | I200: BuildCostRegister, QA, Summary | J200: Header-based mapping required
A201: Resource_Rates | B201: Role | C201: Role field | D201: Text/Number | E201: Yes | F201: Input/Formula | G201: User / FX_Rates | H201: Lists_Config | I201: Manpower_Plan
A202: Resource_Rates | B202: Discipline | C202: Discipline field | D202: Text/Number | E202: Yes | F202: Input/Formula | G202: User / FX_Rates | H202: Lists_Config | I202: Manpower_Plan
A203: Resource_Rates | B203: Location | C203: Location field | D203: Text/Number | E203: Yes | F203: Input/Formula | G203: User / FX_Rates | H203: Lists_Config | I203: Manpower_Plan
A204: Resource_Rates | B204: Currency | C204: Currency field | D204: Text/Number | E204: Yes | F204: Input/Formula | G204: User / FX_Rates | H204: Lists_Config | I204: Manpower_Plan
A205: Resource_Rates | B205: Hourly Rate | C205: Hourly Rate field | D205: Text/Number | E205: Yes | F205: Input/Formula | G205: User / FX_Rates | H205: Lists_Config | I205: Manpower_Plan
A206: Resource_Rates | B206: Hours per Month | C206: Hours per Month field | D206: Text/Number | E206: Yes | F206: Input/Formula | G206: User / FX_Rates | H206: Lists_Config | I206: Manpower_Plan
A207: Resource_Rates | B207: Monthly Rate | C207: Monthly Rate field | D207: Text/Number | E207: Yes | F207: Input/Formula | G207: User / FX_Rates | H207: Lists_Config | I207: Manpower_Plan
A208: Resource_Rates | B208: FX Rate | C208: FX Rate field | D208: Text/Number | E208: Yes | F208: Input/Formula | G208: User / FX_Rates | H208: Lists_Config | I208: Manpower_Plan
A209: Resource_Rates | B209: Monthly Rate EUR | C209: Monthly Rate EUR field | D209: Text/Number | E209: Yes | F209: Input/Formula | G209: User / FX_Rates | H209: Lists_Config | I209: Manpower_Plan
A210: Resource_Rates | B210: Notes | C210: Notes field | D210: Text/Number | E210: No | F210: Input/Formula | G210: User / FX_Rates | H210: Lists_Config | I210: Manpower_Plan
A211: Cost_Register | B211: Source Sheet | C211: Source Sheet normalized field | D211: Text/Number | E211: Yes | F211: Macro Output | G211: Input Sheets | H211: Header validation | I211: All reports | J211: Single source of truth
A212: Cost_Register | B212: Source Row | C212: Source Row normalized field | D212: Text/Number | E212: Yes | F212: Macro Output | G212: Input Sheets | H212: Header validation | I212: All reports | J212: Single source of truth
A213: Cost_Register | B213: Item ID | C213: Item ID normalized field | D213: Text/Number | E213: Yes | F213: Macro Output | G213: Input Sheets | H213: Header validation | I213: All reports | J213: Single source of truth
A214: Cost_Register | B214: Description | C214: Description normalized field | D214: Text/Number | E214: Yes | F214: Macro Output | G214: Input Sheets | H214: Header validation | I214: All reports | J214: Single source of truth
A215: Cost_Register | B215: Discipline | C215: Discipline normalized field | D215: Text/Number | E215: Yes | F215: Macro Output | G215: Input Sheets | H215: Header validation | I215: All reports | J215: Single source of truth
A216: Cost_Register | B216: WBS | C216: WBS normalized field | D216: Text/Number | E216: Yes | F216: Macro Output | G216: Input Sheets | H216: Header validation | I216: All reports | J216: Single source of truth
A217: Cost_Register | B217: CBS | C217: CBS normalized field | D217: Text/Number | E217: Yes | F217: Macro Output | G217: Input Sheets | H217: Header validation | I217: All reports | J217: Single source of truth
A218: Cost_Register | B218: Cost Category | C218: Cost Category normalized field | D218: Text/Number | E218: Yes | F218: Macro Output | G218: Input Sheets | H218: Header validation | I218: All reports | J218: Single source of truth
A219: Cost_Register | B219: Cost Type | C219: Cost Type normalized field | D219: Text/Number | E219: Yes | F219: Macro Output | G219: Input Sheets | H219: Header validation | I219: All reports | J219: Single source of truth
A220: Cost_Register | B220: Quantity | C220: Quantity normalized field | D220: Text/Number | E220: Yes | F220: Macro Output | G220: Input Sheets | H220: Header validation | I220: All reports | J220: Single source of truth
A221: Cost_Register | B221: Unit | C221: Unit normalized field | D221: Text/Number | E221: Yes | F221: Macro Output | G221: Input Sheets | H221: Header validation | I221: All reports | J221: Single source of truth
A222: Cost_Register | B222: Unit Rate | C222: Unit Rate normalized field | D222: Text/Number | E222: Yes | F222: Macro Output | G222: Input Sheets | H222: Header validation | I222: All reports | J222: Single source of truth
... A240: Cost_Register | B240: Notes | C240: Notes normalized field | D240: Text/Number | E240: Yes | F240: Macro Output | G240: Input Sheets | H240: Header validation | I240: All reports | J240: Single source of truth

Sheet Equipment_Estimate
A1: Equipment Estimate
A2: User input layer. Cost_Register must be rebuilt from these sheets via BuildCostRegister.
A4: Item ID | B4: Description | C4: Discipline | D4: WBS | E4: CBS | F4: Cost Category | G4: Cost Type | H4: Quantity | I4: Unit | J4: Unit Rate | K4: Currency | L4: FX Rate | M4: Base Cost | N4: Base Cost EUR | O4: Estimate Basis | P4: Accuracy Low % | Q4: Accuracy High % | R4: Low Cost | S4: Most Likely Cost | T4: High Cost | U4: Contingency Eligible | V4: Escalation Eligible | W4: Spend Category | X4: Phase | Y4: Start Month | Z4: End Month | AA4: Spend Curve | AB4: Notes
A5: EQ-001 | B5: Process mixer package | C5: =IF($D5="","",IFERROR(INDEX(WBS_CBS!$E$5:$E$16,MATCH($D5,WBS_CBS!$A$5:$A$16,0)),"")) | D5: 4.0 | E5: =IF($D5="","",IFERROR(INDEX(WBS_CBS!$C$5:$C$16,MATCH($D5,WBS_CBS!$A$5:$A$16,0)),"")) | F5: =IF($D5="","",IFERROR(INDEX(WBS_CBS!$J$5:$J$16,MATCH($D5,WBS_CBS!$A$5:$A$16,0)),"")) | G5: Equipment | H5: 1 | I5: lot | J5: 2800000 | K5: EUR | L5: =IF($K5="","",IFERROR(INDEX(FX_Rates!$B$5:$B$14,MATCH($K5,FX_Rates!$A$5:$A$14,0)),"")) | M5: =IF(OR($H5="",$J5=""),"",$H5*$J5) | N5: =IF(OR($M5="",$L5=""),"",$M5*$L5) | O5: Class 3 | P5: =IF($O5="","",IFERROR(INDEX(Basis_of_Estimate!$C$5:$C$9,MATCH($O5,Basis_of_Estimate!$A$5:$A$9,0)),"")) | Q5: =IF($O5="","",IFERROR(INDEX(Basis_of_Estimate!$D$5:$D$9,MATCH($O5,Basis_of_Estimate!$A$5:$A$9,0)),"")) | R5: =IF($N5="","",$N5*(1+$P5)) | S5: =IF($N5="","",$N5) | T5: =IF($N5="","",$N5*(1+$Q5)) | U5: =IF($D5="","",IFERROR(INDEX(WBS_CBS!$M$5:$M$16,MATCH($D5,WBS_CBS!$A$5:$A$16,0)),"Yes")) | V5: =IF($D5="","",IFERROR(INDEX(WBS_CBS!$N$5:$N$16,MATCH($D5,WBS_CBS!$A$5:$A$16,0)),"Yes")) | W5: =IF($D5="","",IFERROR(INDEX(WBS_CBS!$K$5:$K$16,MATCH($D5,WBS_CBS!$A$5:$A$16,0)),"")) | X5: =IF($D5="","",IFERROR(INDEX(WBS_CBS!$F$5:$F$16,MATCH($D5,WBS_CBS!$A$5:$A$16,0)),"")) | Y5: 8 | Z5: 18 | AA5: =IF($D5="","",IFERROR(INDEX(WBS_CBS!$L$5:$L$16,MATCH($D5,WBS_CBS!$A$5:$A$16,0)),""))
A6: EQ-002 | B6: Process vessels and tanks | C6: =IF($D6="","",IFERROR(INDEX(WBS_CBS!$E$5:$E$16,MATCH($D6,WBS_CBS!$A$5:$A$16,0)),"")) | D6: 4.0 | E6: =IF($D6="","",IFERROR(INDEX(WBS_CBS!$C$5:$C$16,MATCH($D6,WBS_CBS!$A$5:$A$16,0)),"")) | F6: =IF($D6="","",IFERROR(INDEX(WBS_CBS!$J$5:$J$16,MATCH($D6,WBS_CBS!$A$5:$A$16,0)),"")) | G6: Equipment | H6: 1 | I6: lot | J6: 3200000 | K6: EUR | L6: =IF($K6="","",IFERROR(INDEX(FX_Rates!$B$5:$B$14,MATCH($K6,FX_Rates!$A$5:$A$14,0)),"")) | M6: =IF(OR($H6="",$J6=""),"",$H6*$J6) | N6: =IF(OR($M6="",$L6=""),"",$M6*$L6) | O6: Class 3 | P6: =IF($O6="","",IFERROR(INDEX(Basis_of_Estimate!$C$5:$C$9,MATCH($O6,Basis_of_Estimate!$A$5:$A$9,0)),"")) | Q6: =IF($O6="","",IFERROR(INDEX(Basis_of_Estimate!$D$5:$D$9,MATCH($O6,Basis_of_Estimate!$A$5:$A$9,0)),"")) | R6: =IF($N6="","",$N6*(1+$P6)) | S6: =IF($N6="","",$N6) | T6: =IF($N6="","",$N6*(1+$Q6)) | U6: =IF($D6="","",IFERROR(INDEX(WBS_CBS!$M$5:$M$16,MATCH($D6,WBS_CBS!$A$5:$A$16,0)),"Yes")) | V6: =IF($D6="","",IFERROR(INDEX(WBS_CBS!$N$5:$N$16,MATCH($D6,WBS_CBS!$A$5:$A$16,0)),"Yes")) | W6: =IF($D6="","",IFERROR(INDEX(WBS_CBS!$K$5:$K$16,MATCH($D6,WBS_CBS!$A$5:$A$16,0)),"")) | X6: =IF($D6="","",IFERROR(INDEX(WBS_CBS!$F$5:$F$16,MATCH($D6,WBS_CBS!$A$5:$A$16,0)),"")) | Y6: 6 | Z6: 18 | AA6: =IF($D6="","",IFERROR(INDEX(WBS_CBS!$L$5:$L$16,MATCH($D6,WBS_CBS!$A$5:$A$16,0)),""))
A7: EQ-003 | B7: Pumping and transfer skids | C7: =IF($D7="","",IFERROR(INDEX(WBS_CBS!$E$5:$E$16,MATCH($D7,WBS_CBS!$A$5:$A$16,0)),"")) | D7: 4.0 | E7: =IF($D7="","",IFERROR(INDEX(WBS_CBS!$C$5:$C$16,MATCH($D7,WBS_CBS!$A$5:$A$16,0)),"")) | F7: =IF($D7="","",IFERROR(INDEX(WBS_CBS!$J$5:$J$16,MATCH($D7,WBS_CBS!$A$5:$A$16,0)),"")) | G7: Equipment | H7: 1 | I7: lot | J7: 2000000 | K7: EUR | L7: =IF($K7="","",IFERROR(INDEX(FX_Rates!$B$5:$B$14,MATCH($K7,FX_Rates!$A$5:$A$14,0)),"")) | M7: =IF(OR($H7="",$J7=""),"",$H7*$J7) | N7: =IF(OR($M7="",$L7=""),"",$M7*$L7) | O7: Class 3 | P7: =IF($O7="","",IFERROR(INDEX(Basis_of_Estimate!$C$5:$C$9,MATCH($O7,Basis_of_Estimate!$A$5:$A$9,0)),"")) | Q7: =IF($O7="","",IFERROR(INDEX(Basis_of_Estimate!$D$5:$D$9,MATCH($O7,Basis_of_Estimate!$A$5:$A$9,0)),"")) | R7: =IF($N7="","",$N7*(1+$P7)) | S7: =IF($N7="","",$N7) | T7: =IF($N7="","",$N7*(1+$Q7)) | U7: =IF($D7="","",IFERROR(INDEX(WBS_CBS!$M$5:$M$16,MATCH($D7,WBS_CBS!$A$5:$A$16,0)),"Yes")) | V7: =IF($D7="","",IFERROR(INDEX(WBS_CBS!$N$5:$N$16,MATCH($D7,WBS_CBS!$A$5:$A$16,0)),"Yes")) | W7: =IF($D7="","",IFERROR(INDEX(WBS_CBS!$K$5:$K$16,MATCH($D7,WBS_CBS!$A$5:$A$16,0)),"")) | X7: =IF($D7="","",IFERROR(INDEX(WBS_CBS!$F$5:$F$16,MATCH($D7,WBS_CBS!$A$5:$A$16,0)),"")) | Y7: 10 | Z7: 20 | AA7: =IF($D7="","",IFERROR(INDEX(WBS_CBS!$L$5:$L$16,MATCH($D7,WBS_CBS!$A$5:$A$16,0)),""))
A8: EQ-004 | B8: Heat exchangers and utility skids | C8: =IF($D8="","",IFERROR(INDEX(WBS_CBS!$E$5:$E$16,MATCH($D8,WBS_CBS!$A$5:$A$16,0)),"")) | D8: 4.0 | E8: =IF($D8="","",IFERROR(INDEX(WBS_CBS!$C$5:$C$16,MATCH($D8,WBS_CBS!$A$5:$A$16,0)),"")) | F8: =IF($D8="","",IFERROR(INDEX(WBS_CBS!$J$5:$J$16,MATCH($D8,WBS_CBS!$A$5:$A$16,0)),"")) | G8: Equipment | H8: 1 | I8: lot | J8: 2400000 | K8: EUR | L8: =IF($K8="","",IFERROR(INDEX(FX_Rates!$B$5:$B$14,MATCH($K8,FX_Rates!$A$5:$A$14,0)),"")) | M8: =IF(OR($H8="",$J8=""),"",$H8*$J8) | N8: =IF(OR($M8="",$L8=""),"",$M8*$L8) | O8: Class 3 | P8: =IF($O8="","",IFERROR(INDEX(Basis_of_Estimate!$C$5:$C$9,MATCH($O8,Basis_of_Estimate!$A$5:$A$9,0)),"")) | Q8: =IF($O8="","",IFERROR(INDEX(Basis_of_Estimate!$D$5:$D$9,MATCH($O8,Basis_of_Estimate!$A$5:$A$9,0)),"")) | R8: =IF($N8="","",$N8*(1+$P8)) | S8: =IF($N8="","",$N8) | T8: =IF($N8="","",$N8*(1+$Q8)) | U8: =IF($D8="","",IFERROR(INDEX(WBS_CBS!$M$5:$M$16,MATCH($D8,WBS_CBS!$A$5:$A$16,0)),"Yes")) | V8: =IF($D8="","",IFERROR(INDEX(WBS_CBS!$N$5:$N$16,MATCH($D8,WBS_CBS!$A$5:$A$16,0)),"Yes")) | W8: =IF($D8="","",IFERROR(INDEX(WBS_CBS!$K$5:$K$16,MATCH($D8,WBS_CBS!$A$5:$A$16,0)),"")) | X8: =IF($D8="","",IFERROR(INDEX(WBS_CBS!$F$5:$F$16,MATCH($D8,WBS_CBS!$A$5:$A$16,0)),"")) | Y8: 9 | Z8: 21 | AA8: =IF($D8="","",IFERROR(INDEX(WBS_CBS!$L$5:$L$16,MATCH($D8,WBS_CBS!$A$5:$A$16,0)),""))
A9: EQ-005 | B9: Equipment installation auxiliaries | C9: =IF($D9="","",IFERROR(INDEX(WBS_CBS!$E$5:$E$16,MATCH($D9,WBS_CBS!$A$5:$A$16,0)),"")) | D9: 4.0 | E9: =IF($D9="","",IFERROR(INDEX(WBS_CBS!$C$5:$C$16,MATCH($D9,WBS_CBS!$A$5:$A$16,0)),"")) | F9: =IF($D9="","",IFERROR(INDEX(WBS_CBS!$J$5:$J$16,MATCH($D9,WBS_CBS!$A$5:$A$16,0)),"")) | G9: Equipment | H9: 1 | I9: lot | J9: 1600000 | K9: EUR | L9: =IF($K9="","",IFERROR(INDEX(FX_Rates!$B$5:$B$14,MATCH($K9,FX_Rates!$A$5:$A$14,0)),"")) | M9: =IF(OR($H9="",$J9=""),"",$H9*$J9) | N9: =IF(OR($M9="",$L9=""),"",$M9*$L9) | O9: Class 3 | P9: =IF($O9="","",IFERROR(INDEX(Basis_of_Estimate!$C$5:$C$9,MATCH($O9,Basis_of_Estimate!$A$5:$A$9,0)),"")) | Q9: =IF($O9="","",IFERROR(INDEX(Basis_of_Estimate!$D$5:$D$9,MATCH($O9,Basis_of_Estimate!$A$5:$A$9,0)),"")) | R9: =IF($N9="","",$N9*(1+$P9)) | S9: =IF($N9="","",$N9) | T9: =IF($N9="","",$N9*(1+$Q9)) | U9: =IF($D9="","",IFERROR(INDEX(WBS_CBS!$M$5:$M$16,MATCH($D9,WBS_CBS!$A$5:$A$16,0)),"Yes")) | V9: =IF($D9="","",IFERROR(INDEX(WBS_CBS!$N$5:$N$16,MATCH($D9,WBS_CBS!$A$5:$A$16,0)),"Yes")) | W9: =IF($D9="","",IFERROR(INDEX(WBS_CBS!$K$5:$K$16,MATCH($D9,WBS_CBS!$A$5:$A$16,0)),"")) | X9: =IF($D9="","",IFERROR(INDEX(WBS_CBS!$F$5:$F$16,MATCH($D9,WBS_CBS!$A$5:$A$16,0)),"")) | Y9: 14 | Z9: 27 | AA9: =IF($D9="","",IFERROR(INDEX(WBS_CBS!$L$5:$L$16,MATCH($D9,WBS_CBS!$A$5:$A$16,0)),""))
C10: =IF($D10="","",IFERROR(INDEX(WBS_CBS!$E$5:$E$16,MATCH($D10,WBS_CBS!$A$5:$A$16,0)),"")) | E10: =IF($D10="","",IFERROR(INDEX(WBS_CBS!$C$5:$C$16,MATCH($D10,WBS_CBS!$A$5:$A$16,0)),"")) | F10: =IF($D10="","",IFERROR(INDEX(WBS_CBS!$J$5:$J$16,MATCH($D10,WBS_CBS!$A$5:$A$16,0)),"")) | L10: =IF($K10="","",IFERROR(INDEX(FX_Rates!$B$5:$B$14,MATCH($K10,FX_Rates!$A$5:$A$14,0)),"")) | M10: =IF(OR($H10="",$J10=""),"",$H10*$J10) | N10: =IF(OR($M10="",$L10=""),"",$M10*$L10) | P10: =IF($O10="","",IFERROR(INDEX(Basis_of_Estimate!$C$5:$C$9,MATCH($O10,Basis_of_Estimate!$A$5:$A$9,0)),"")) | Q10: =IF($O10="","",IFERROR(INDEX(Basis_of_Estimate!$D$5:$D$9,MATCH($O10,Basis_of_Estimate!$A$5:$A$9,0)),"")) | R10: =IF($N10="","",$N10*(1+$P10)) | S10: =IF($N10="","",$N10) | T10: =IF($N10="","",$N10*(1+$Q10)) | U10: =IF($D10="","",IFERROR(INDEX(WBS_CBS!$M$5:$M$16,MATCH($D10,WBS_CBS!$A$5:$A$16,0)),"Yes")) | V10: =IF($D10="","",IFERROR(INDEX(WBS_CBS!$N$5:$N$16,MATCH($D10,WBS_CBS!$A$5:$A$16,0)),"Yes")) | W10: =IF($D10="","",IFERROR(INDEX(WBS_CBS!$K$5:$K$16,MATCH($D10,WBS_CBS!$A$5:$A$16,0)),"")) | X10: =IF($D10="","",IFERROR(INDEX(WBS_CBS!$F$5:$F$16,MATCH($D10,WBS_CBS!$A$5:$A$16,0)),"")) | AA10: =IF($D10="","",IFERROR(INDEX(WBS_CBS!$L$5:$L$16,MATCH($D10,WBS_CBS!$A$5:$A$16,0)),""))
C11: =IF($D11="","",IFERROR(INDEX(WBS_CBS!$E$5:$E$16,MATCH($D11,WBS_CBS!$A$5:$A$16,0)),"")) | E11: =IF($D11="","",IFERROR(INDEX(WBS_CBS!$C$5:$C$16,MATCH($D11,WBS_CBS!$A$5:$A$16,0)),"")) | F11: =IF($D11="","",IFERROR(INDEX(WBS_CBS!$J$5:$J$16,MATCH($D11,WBS_CBS!$A$5:$A$16,0)),"")) | L11: =IF($K11="","",IFERROR(INDEX(FX_Rates!$B$5:$B$14,MATCH($K11,FX_Rates!$A$5:$A$14,0)),"")) | M11: =IF(OR($H11="",$J11=""),"",$H11*$J11) | N11: =IF(OR($M11="",$L11=""),"",$M11*$L11) | P11: =IF($O11="","",IFERROR(INDEX(Basis_of_Estimate!$C$5:$C$9,MATCH($O11,Basis_of_Estimate!$A$5:$A$9,0)),"")) | Q11: =IF($O11="","",IFERROR(INDEX(Basis_of_Estimate!$D$5:$D$9,MATCH($O11,Basis_of_Estimate!$A$5:$A$9,0)),"")) | R11: =IF($N11="","",$N11*(1+$P11)) | S11: =IF($N11="","",$N11) | T11: =IF($N11="","",$N11*(1+$Q11)) | U11: =IF($D11="","",IFERROR(INDEX(WBS_CBS!$M$5:$M$16,MATCH($D11,WBS_CBS!$A$5:$A$16,0)),"Yes")) | V11: =IF($D11="","",IFERROR(INDEX(WBS_CBS!$N$5:$N$16,MATCH($D11,WBS_CBS!$A$5:$A$16,0)),"Yes")) | W11: =IF($D11="","",IFERROR(INDEX(WBS_CBS!$K$5:$K$16,MATCH($D11,WBS_CBS!$A$5:$A$16,0)),"")) | X11: =IF($D11="","",IFERROR(INDEX(WBS_CBS!$F$5:$F$16,MATCH($D11,WBS_CBS!$A$5:$A$16,0)),"")) | AA11: =IF($D11="","",IFERROR(INDEX(WBS_CBS!$L$5:$L$16,MATCH($D11,WBS_CBS!$A$5:$A$16,0)),""))
C12: =IF($D12="","",IFERROR(INDEX(WBS_CBS!$E$5:$E$16,MATCH($D12,WBS_CBS!$A$5:$A$16,0)),"")) | E12: =IF($D12="","",IFERROR(INDEX(WBS_CBS!$C$5:$C$16,MATCH($D12,WBS_CBS!$A$5:$A$16,0)),"")) | F12: =IF($D12="","",IFERROR(INDEX(WBS_CBS!$J$5:$J$16,MATCH($D12,WBS_CBS!$A$5:$A$16,0)),"")) | L12: =IF($K12="","",IFERROR(INDEX(FX_Rates!$B$5:$B$14,MATCH($K12,FX_Rates!$A$5:$A$14,0)),"")) | M12: =IF(OR($H12="",$J12=""),"",$H12*$J12) | N12: =IF(OR($M12="",$L12=""),"",$M12*$L12) | P12: =IF($O12="","",IFERROR(INDEX(Basis_of_Estimate!$C$5:$C$9,MATCH($O12,Basis_of_Estimate!$A$5:$A$9,0)),"")) | Q12: =IF($O12="","",IFERROR(INDEX(Basis_of_Estimate!$D$5:$D$9,MATCH($O12,Basis_of_Estimate!$A$5:$A$9,0)),"")) | R12: =IF($N12="","",$N12*(1+$P12)) | S12: =IF($N12="","",$N12) | T12: =IF($N12="","",$N12*(1+$Q12)) | U12: =IF($D12="","",IFERROR(INDEX(WBS_CBS!$M$5:$M$16,MATCH($D12,WBS_CBS!$A$5:$A$16,0)),"Yes")) | V12: =IF($D12="","",IFERROR(INDEX(WBS_CBS!$N$5:$N$16,MATCH($D12,WBS_CBS!$A$5:$A$16,0)),"Yes")) | W12: =IF($D12="","",IFERROR(INDEX(WBS_CBS!$K$5:$K$16,MATCH($D12,WBS_CBS!$A$5:$A$16,0)),"")) | X12: =IF($D12="","",IFERROR(INDEX(WBS_CBS!$F$5:$F$16,MATCH($D12,WBS_CBS!$A$5:$A$16,0)),"")) | AA12: =IF($D12="","",IFERROR(INDEX(WBS_CBS!$L$5:$L$16,MATCH($D12,WBS_CBS!$A$5:$A$16,0)),""))
C13: =IF($D13="","",IFERROR(INDEX(WBS_CBS!$E$5:$E$16,MATCH($D13,WBS_CBS!$A$5:$A$16,0)),"")) | E13: =IF($D13="","",IFERROR(INDEX(WBS_CBS!$C$5:$C$16,MATCH($D13,WBS_CBS!$A$5:$A$16,0)),"")) | F13: =IF($D13="","",IFERROR(INDEX(WBS_CBS!$J$5:$J$16,MATCH($D13,WBS_CBS!$A$5:$A$16,0)),"")) | L13: =IF($K13="","",IFERROR(INDEX(FX_Rates!$B$5:$B$14,MATCH($K13,FX_Rates!$A$5:$A$14,0)),"")) | M13: =IF(OR($H13="",$J13=""),"",$H13*$J13) | N13: =IF(OR($M13="",$L13=""),"",$M13*$L13) | P13: =IF($O13="","",IFERROR(INDEX(Basis_of_Estimate!$C$5:$C$9,MATCH($O13,Basis_of_Estimate!$A$5:$A$9,0)),"")) | Q13: =IF($O13="","",IFERROR(INDEX(Basis_of_Estimate!$D$5:$D$9,MATCH($O13,Basis_of_Estimate!$A$5:$A$9,0)),"")) | R13: =IF($N13="","",$N13*(1+$P13)) | S13: =IF($N13="","",$N13) | T13: =IF($N13="","",$N13*(1+$Q13)) | U13: =IF($D13="","",IFERROR(INDEX(WBS_CBS!$M$5:$M$16,MATCH($D13,WBS_CBS!$A$5:$A$16,0)),"Yes")) | V13: =IF($D13="","",IFERROR(INDEX(WBS_CBS!$N$5:$N$16,MATCH($D13,WBS_CBS!$A$5:$A$16,0)),"Yes")) | W13: =IF($D13="","",IFERROR(INDEX(WBS_CBS!$K$5:$K$16,MATCH($D13,WBS_CBS!$A$5:$A$16,0)),"")) | X13: =IF($D13="","",IFERROR(INDEX(WBS_CBS!$F$5:$F$16,MATCH($D13,WBS_CBS!$A$5:$A$16,0)),"")) | AA13: =IF($D13="","",IFERROR(INDEX(WBS_CBS!$L$5:$L$16,MATCH($D13,WBS_CBS!$A$5:$A$16,0)),""))
C14: =IF($D14="","",IFERROR(INDEX(WBS_CBS!$E$5:$E$16,MATCH($D14,WBS_CBS!$A$5:$A$16,0)),"")) | E14: =IF($D14="","",IFERROR(INDEX(WBS_CBS!$C$5:$C$16,MATCH($D14,WBS_CBS!$A$5:$A$16,0)),"")) | F14: =IF($D14="","",IFERROR(INDEX(WBS_CBS!$J$5:$J$16,MATCH($D14,WBS_CBS!$A$5:$A$16,0)),"")) | L14: =IF($K14="","",IFERROR(INDEX(FX_Rates!$B$5:$B$14,MATCH($K14,FX_Rates!$A$5:$A$14,0)),"")) | M14: =IF(OR($H14="",$J14=""),"",$H14*$J14) | N14: =IF(OR($M14="",$L14=""),"",$M14*$L14) | P14: =IF($O14="","",IFERROR(INDEX(Basis_of_Estimate!$C$5:$C$9,MATCH($O14,Basis_of_Estimate!$A$5:$A$9,0)),"")) | Q14: =IF($O14="","",IFERROR(INDEX(Basis_of_Estimate!$D$5:$D$9,MATCH($O14,Basis_of_Estimate!$A$5:$A$9,0)),"")) | R14: =IF($N14="","",$N14*(1+$P14)) | S14: =IF($N14="","",$N14) | T14: =IF($N14="","",$N14*(1+$Q14)) | U14: =IF($D14="","",IFERROR(INDEX(WBS_CBS!$M$5:$M$16,MATCH($D14,WBS_CBS!$A$5:$A$16,0)),"Yes")) | V14: =IF($D14="","",IFERROR(INDEX(WBS_CBS!$N$5:$N$16,MATCH($D14,WBS_CBS!$A$5:$A$16,0)),"Yes")) | W14: =IF($D14="","",IFERROR(INDEX(WBS_CBS!$K$5:$K$16,MATCH($D14,WBS_CBS!$A$5:$A$16,0)),"")) | X14: =IF($D14="","",IFERROR(INDEX(WBS_CBS!$F$5:$F$16,MATCH($D14,WBS_CBS!$A$5:$A$16,0)),"")) | AA14: =IF($D14="","",IFERROR(INDEX(WBS_CBS!$L$5:$L$16,MATCH($D14,WBS_CBS!$A$5:$A$16,0)),""))
C15: =IF($D15="","",IFERROR(INDEX(WBS_CBS!$E$5:$E$16,MATCH($D15,WBS_CBS!$A$5:$A$16,0)),"")) | E15: =IF($D15="","",IFERROR(INDEX(WBS_CBS!$C$5:$C$16,MATCH($D15,WBS_CBS!$A$5:$A$16,0)),"")) | F15: =IF($D15="","",IFERROR(INDEX(WBS_CBS!$J$5:$J$16,MATCH($D15,WBS_CBS!$A$5:$A$16,0)),"")) | L15: =IF($K15="","",IFERROR(INDEX(FX_Rates!$B$5:$B$14,MATCH($K15,FX_Rates!$A$5:$A$14,0)),"")) | M15: =IF(OR($H15="",$J15=""),"",$H15*$J15) | N15: =IF(OR($M15="",$L15=""),"",$M15*$L15) | P15: =IF($O15="","",IFERROR(INDEX(Basis_of_Estimate!$C$5:$C$9,MATCH($O15,Basis_of_Estimate!$A$5:$A$9,0)),"")) | Q15: =IF($O15="","",IFERROR(INDEX(Basis_of_Estimate!$D$5:$D$9,MATCH($O15,Basis_of_Estimate!$A$5:$A$9,0)),"")) | R15: =IF($N15="","",$N15*(1+$P15)) | S15: =IF($N15="","",$N15) | T15: =IF($N15="","",$N15*(1+$Q15)) | U15: =IF($D15="","",IFERROR(INDEX(WBS_CBS!$M$5:$M$16,MATCH($D15,WBS_CBS!$A$5:$A$16,0)),"Yes")) | V15: =IF($D15="","",IFERROR(INDEX(WBS_CBS!$N$5:$N$16,MATCH($D15,WBS_CBS!$A$5:$A$16,0)),"Yes")) | W15: =IF($D15="","",IFERROR(INDEX(WBS_CBS!$K$5:$K$16,MATCH($D15,WBS_CBS!$A$5:$A$16,0)),"")) | X15: =IF($D15="","",IFERROR(INDEX(WBS_CBS!$F$5:$F$16,MATCH($D15,WBS_CBS!$A$5:$A$16,0)),"")) | AA15: =IF($D15="","",IFERROR(INDEX(WBS_CBS!$L$5:$L$16,MATCH($D15,WBS_CBS!$A$5:$A$16,0)),""))
C16: =IF($D16="","",IFERROR(INDEX(WBS_CBS!$E$5:$E$16,MATCH($D16,WBS_CBS!$A$5:$A$16,0)),"")) | E16: =IF($D16="","",IFERROR(INDEX(WBS_CBS!$C$5:$C$16,MATCH($D16,WBS_CBS!$A$5:$A$16,0)),"")) | F16: =IF($D16="","",IFERROR(INDEX(WBS_CBS!$J$5:$J$16,MATCH($D16,WBS_CBS!$A$5:$A$16,0)),"")) | L16: =IF($K16="","",IFERROR(INDEX(FX_Rates!$B$5:$B$14,MATCH($K16,FX_Rates!$A$5:$A$14,0)),"")) | M16: =IF(OR($H16="",$J16=""),"",$H16*$J16) | N16: =IF(OR($M16="",$L16=""),"",$M16*$L16) | P16: =IF($O16="","",IFERROR(INDEX(Basis_of_Estimate!$C$5:$C$9,MATCH($O16,Basis_of_Estimate!$A$5:$A$9,0)),"")) | Q16: =IF($O16="","",IFERROR(INDEX(Basis_of_Estimate!$D$5:$D$9,MATCH($O16,Basis_of_Estimate!$A$5:$A$9,0)),"")) | R16: =IF($N16="","",$N16*(1+$P16)) | S16: =IF($N16="","",$N16) | T16: =IF($N16="","",$N16*(1+$Q16)) | U16: =IF($D16="","",IFERROR(INDEX(WBS_CBS!$M$5:$M$16,MATCH($D16,WBS_CBS!$A$5:$A$16,0)),"Yes")) | V16: =IF($D16="","",IFERROR(INDEX(WBS_CBS!$N$5:$N$16,MATCH($D16,WBS_CBS!$A$5:$A$16,0)),"Yes")) | W16: =IF($D16="","",IFERROR(INDEX(WBS_CBS!$K$5:$K$16,MATCH($D16,WBS_CBS!$A$5:$A$16,0)),"")) | X16: =IF($D16="","",IFERROR(INDEX(WBS_CBS!$F$5:$F$16,MATCH($D16,WBS_CBS!$A$5:$A$16,0)),"")) | AA16: =IF($D16="","",IFERROR(INDEX(WBS_CBS!$L$5:$L$16,MATCH($D16,WBS_CBS!$A$5:$A$16,0)),""))
C17: =IF($D17="","",IFERROR(INDEX(WBS_CBS!$E$5:$E$16,MATCH($D17,WBS_CBS!$A$5:$A$16,0)),"")) | E17: =IF($D17="","",IFERROR(INDEX(WBS_CBS!$C$5:$C$16,MATCH($D17,WBS_CBS!$A$5:$A$16,0)),"")) | F17: =IF($D17="","",IFERROR(INDEX(WBS_CBS!$J$5:$J$16,MATCH($D17,WBS_CBS!$A$5:$A$16,0)),"")) | L17: =IF($K17="","",IFERROR(INDEX(FX_Rates!$B$5:$B$14,MATCH($K17,FX_Rates!$A$5:$A$14,0)),"")) | M17: =IF(OR($H17="",$J17=""),"",$H17*$J17) | N17: =IF(OR($M17="",$L17=""),"",$M17*$L17) | P17: =IF($O17="","",IFERROR(INDEX(Basis_of_Estimate!$C$5:$C$9,MATCH($O17,Basis_of_Estimate!$A$5:$A$9,0)),"")) | Q17: =IF($O17="","",IFERROR(INDEX(Basis_of_Estimate!$D$5:$D$9,MATCH($O17,Basis_of_Estimate!$A$5:$A$9,0)),"")) | R17: =IF($N17="","",$N17*(1+$P17)) | S17: =IF($N17="","",$N17) | T17: =IF($N17="","",$N17*(1+$Q17)) | U17: =IF($D17="","",IFERROR(INDEX(WBS_CBS!$M$5:$M$16,MATCH($D17,WBS_CBS!$A$5:$A$16,0)),"Yes")) | V17: =IF($D17="","",IFERROR(INDEX(WBS_CBS!$N$5:$N$16,MATCH($D17,WBS_CBS!$A$5:$A$16,0)),"Yes")) | W17: =IF($D17="","",IFERROR(INDEX(WBS_CBS!$K$5:$K$16,MATCH($D17,WBS_CBS!$A$5:$A$16,0)),"")) | X17: =IF($D17="","",IFERROR(INDEX(WBS_CBS!$F$5:$F$16,MATCH($D17,WBS_CBS!$A$5:$A$16,0)),"")) | AA17: =IF($D17="","",IFERROR(INDEX(WBS_CBS!$L$5:$L$16,MATCH($D17,WBS_CBS!$A$5:$A$16,0)),""))
C18: =IF($D18="","",IFERROR(INDEX(WBS_CBS!$E$5:$E$16,MATCH($D18,WBS_CBS!$A$5:$A$16,0)),"")) | E18: =IF($D18="","",IFERROR(INDEX(WBS_CBS!$C$5:$C$16,MATCH($D18,WBS_CBS!$A$5:$A$16,0)),"")) | F18: =IF($D18="","",IFERROR(INDEX(WBS_CBS!$J$5:$J$16,MATCH($D18,WBS_CBS!$A$5:$A$16,0)),"")) | L18: =IF($K18="","",IFERROR(INDEX(FX_Rates!$B$5:$B$14,MATCH($K18,FX_Rates!$A$5:$A$14,0)),"")) | M18: =IF(OR($H18="",$J18=""),"",$H18*$J18) | N18: =IF(OR($M18="",$L18=""),"",$M18*$L18) | P18: =IF($O18="","",IFERROR(INDEX(Basis_of_Estimate!$C$5:$C$9,MATCH($O18,Basis_of_Estimate!$A$5:$A$9,0)),"")) | Q18: =IF($O18="","",IFERROR(INDEX(Basis_of_Estimate!$D$5:$D$9,MATCH($O18,Basis_of_Estimate!$A$5:$A$9,0)),"")) | R18: =IF($N18="","",$N18*(1+$P18)) | S18: =IF($N18="","",$N18) | T18: =IF($N18="","",$N18*(1+$Q18)) | U18: =IF($D18="","",IFERROR(INDEX(WBS_CBS!$M$5:$M$16,MATCH($D18,WBS_CBS!$A$5:$A$16,0)),"Yes")) | V18: =IF($D18="","",IFERROR(INDEX(WBS_CBS!$N$5:$N$16,MATCH($D18,WBS_CBS!$A$5:$A$16,0)),"Yes")) | W18: =IF($D18="","",IFERROR(INDEX(WBS_CBS!$K$5:$K$16,MATCH($D18,WBS_CBS!$A$5:$A$16,0)),"")) | X18: =IF($D18="","",IFERROR(INDEX(WBS_CBS!$F$5:$F$16,MATCH($D18,WBS_CBS!$A$5:$A$16,0)),"")) | AA18: =IF($D18="","",IFERROR(INDEX(WBS_CBS!$L$5:$L$16,MATCH($D18,WBS_CBS!$A$5:$A$16,0)),""))
C19: =IF($D19="","",IFERROR(INDEX(WBS_CBS!$E$5:$E$16,MATCH($D19,WBS_CBS!$A$5:$A$16,0)),"")) | E19: =IF($D19="","",IFERROR(INDEX(WBS_CBS!$C$5:$C$16,MATCH($D19,WBS_CBS!$A$5:$A$16,0)),"")) | F19: =IF($D19="","",IFERROR(INDEX(WBS_CBS!$J$5:$J$16,MATCH($D19,WBS_CBS!$A$5:$A$16,0)),"")) | L19: =IF($K19="","",IFERROR(INDEX(FX_Rates!$B$5:$B$14,MATCH($K19,FX_Rates!$A$5:$A$14,0)),"")) | M19: =IF(OR($H19="",$J19=""),"",$H19*$J19) | N19: =IF(OR($M19="",$L19=""),"",$M19*$L19) | P19: =IF($O19="","",IFERROR(INDEX(Basis_of_Estimate!$C$5:$C$9,MATCH($O19,Basis_of_Estimate!$A$5:$A$9,0)),"")) | Q19: =IF($O19="","",IFERROR(INDEX(Basis_of_Estimate!$D$5:$D$9,MATCH($O19,Basis_of_Estimate!$A$5:$A$9,0)),"")) | R19: =IF($N19="","",$N19*(1+$P19)) | S19: =IF($N19="","",$N19) | T19: =IF($N19="","",$N19*(1+$Q19)) | U19: =IF($D19="","",IFERROR(INDEX(WBS_CBS!$M$5:$M$16,MATCH($D19,WBS_CBS!$A$5:$A$16,0)),"Yes")) | V19: =IF($D19="","",IFERROR(INDEX(WBS_CBS!$N$5:$N$16,MATCH($D19,WBS_CBS!$A$5:$A$16,0)),"Yes")) | W19: =IF($D19="","",IFERROR(INDEX(WBS_CBS!$K$5:$K$16,MATCH($D19,WBS_CBS!$A$5:$A$16,0)),"")) | X19: =IF($D19="","",IFERROR(INDEX(WBS_CBS!$F$5:$F$16,MATCH($D19,WBS_CBS!$A$5:$A$16,0)),"")) | AA19: =IF($D19="","",IFERROR(INDEX(WBS_CBS!$L$5:$L$16,MATCH($D19,WBS_CBS!$A$5:$A$16,0)),""))
C20: =IF($D20="","",IFERROR(INDEX(WBS_CBS!$E$5:$E$16,MATCH($D20,WBS_CBS!$A$5:$A$16,0)),"")) | E20: =IF($D20="","",IFERROR(INDEX(WBS_CBS!$C$5:$C$16,MATCH($D20,WBS_CBS!$A$5:$A$16,0)),"")) | F20: =IF($D20="","",IFERROR(INDEX(WBS_CBS!$J$5:$J$16,MATCH($D20,WBS_CBS!$A$5:$A$16,0)),"")) | L20: =IF($K20="","",IFERROR(INDEX(FX_Rates!$B$5:$B$14,MATCH($K20,FX_Rates!$A$5:$A$14,0)),"")) | M20: =IF(OR($H20="",$J20=""),"",$H20*$J20) | N20: =IF(OR($M20="",$L20=""),"",$M20*$L20) | P20: =IF($O20="","",IFERROR(INDEX(Basis_of_Estimate!$C$5:$C$9,MATCH($O20,Basis_of_Estimate!$A$5:$A$9,0)),"")) | Q20: =IF($O20="","",IFERROR(INDEX(Basis_of_Estimate!$D$5:$D$9,MATCH($O20,Basis_of_Estimate!$A$5:$A$9,0)),"")) | R20: =IF($N20="","",$N20*(1+$P20)) | S20: =IF($N20="","",$N20) | T20: =IF($N20="","",$N20*(1+$Q20)) | U20: =IF($D20="","",IFERROR(INDEX(WBS_CBS!$M$5:$M$16,MATCH($D20,WBS_CBS!$A$5:$A$16,0)),"Yes")) | V20: =IF($D20="","",IFERROR(INDEX(WBS_CBS!$N$5:$N$16,MATCH($D20,WBS_CBS!$A$5:$A$16,0)),"Yes")) | W20: =IF($D20="","",IFERROR(INDEX(WBS_CBS!$K$5:$K$16,MATCH($D20,WBS_CBS!$A$5:$A$16,0)),"")) | X20: =IF($D20="","",IFERROR(INDEX(WBS_CBS!$F$5:$F$16,MATCH($D20,WBS_CBS!$A$5:$A$16,0)),"")) | AA20: =IF($D20="","",IFERROR(INDEX(WBS_CBS!$L$5:$L$16,MATCH($D20,WBS_CBS!$A$5:$A$16,0)),""))
C21: =IF($D21="","",IFERROR(INDEX(WBS_CBS!$E$5:$E$16,MATCH($D21,WBS_CBS!$A$5:$A$16,0)),"")) | E21: =IF($D21="","",IFERROR(INDEX(WBS_CBS!$C$5:$C$16,MATCH($D21,WBS_CBS!$A$5:$A$16,0)),"")) | F21: =IF($D21="","",IFERROR(INDEX(WBS_CBS!$J$5:$J$16,MATCH($D21,WBS_CBS!$A$5:$A$16,0)),"")) | L21: =IF($K21="","",IFERROR(INDEX(FX_Rates!$B$5:$B$14,MATCH($K21,FX_Rates!$A$5:$A$14,0)),"")) | M21: =IF(OR($H21="",$J21=""),"",$H21*$J21) | N21: =IF(OR($M21="",$L21=""),"",$M21*$L21) | P21: =IF($O21="","",IFERROR(INDEX(Basis_of_Estimate!$C$5:$C$9,MATCH($O21,Basis_of_Estimate!$A$5:$A$9,0)),"")) | Q21: =IF($O21="","",IFERROR(INDEX(Basis_of_Estimate!$D$5:$D$9,MATCH($O21,Basis_of_Estimate!$A$5:$A$9,0)),"")) | R21: =IF($N21="","",$N21*(1+$P21)) | S21: =IF($N21="","",$N21) | T21: =IF($N21="","",$N21*(1+$Q21)) | U21: =IF($D21="","",IFERROR(INDEX(WBS_CBS!$M$5:$M$16,MATCH($D21,WBS_CBS!$A$5:$A$16,0)),"Yes")) | V21: =IF($D21="","",IFERROR(INDEX(WBS_CBS!$N$5:$N$16,MATCH($D21,WBS_CBS!$A$5:$A$16,0)),"Yes")) | W21: =IF($D21="","",IFERROR(INDEX(WBS_CBS!$K$5:$K$16,MATCH($D21,WBS_CBS!$A$5:$A$16,0)),"")) | X21: =IF($D21="","",IFERROR(INDEX(WBS_CBS!$F$5:$F$16,MATCH($D21,WBS_CBS!$A$5:$A$16,0)),"")) | AA21: =IF($D21="","",IFERROR(INDEX(WBS_CBS!$L$5:$L$16,MATCH($D21,WBS_CBS!$A$5:$A$16,0)),""))
... C104: =IF($D104="","",IFERROR(INDEX(WBS_CBS!$E$5:$E$16,MATCH($D104,WBS_CBS!$A$5:$A$16,0)),"")) | E104: =IF($D104="","",IFERROR(INDEX(WBS_CBS!$C$5:$C$16,MATCH($D104,WBS_CBS!$A$5:$A$16,0)),"")) | F104: =IF($D104="","",IFERROR(INDEX(WBS_CBS!$J$5:$J$16,MATCH($D104,WBS_CBS!$A$5:$A$16,0)),"")) | L104: =IF($K104="","",IFERROR(INDEX(FX_Rates!$B$5:$B$14,MATCH($K104,FX_Rates!$A$5:$A$14,0)),"")) | M104: =IF(OR($H104="",$J104=""),"",$H104*$J104) | N104: =IF(OR($M104="",$L104=""),"",$M104*$L104) | P104: =IF($O104="","",IFERROR(INDEX(Basis_of_Estimate!$C$5:$C$9,MATCH($O104,Basis_of_Estimate!$A$5:$A$9,0)),"")) | Q104: =IF($O104="","",IFERROR(INDEX(Basis_of_Estimate!$D$5:$D$9,MATCH($O104,Basis_of_Estimate!$A$5:$A$9,0)),"")) | R104: =IF($N104="","",$N104*(1+$P104)) | S104: =IF($N104="","",$N104) | T104: =IF($N104="","",$N104*(1+$Q104)) | U104: =IF($D104="","",IFERROR(INDEX(WBS_CBS!$M$5:$M$16,MATCH($D104,WBS_CBS!$A$5:$A$16,0)),"Yes")) | V104: =IF($D104="","",IFERROR(INDEX(WBS_CBS!$N$5:$N$16,MATCH($D104,WBS_CBS!$A$5:$A$16,0)),"Yes")) | W104: =IF($D104="","",IFERROR(INDEX(WBS_CBS!$K$5:$K$16,MATCH($D104,WBS_CBS!$A$5:$A$16,0)),"")) | X104: =IF($D104="","",IFERROR(INDEX(WBS_CBS!$F$5:$F$16,MATCH($D104,WBS_CBS!$A$5:$A$16,0)),"")) | AA104: =IF($D104="","",IFERROR(INDEX(WBS_CBS!$L$5:$L$16,MATCH($D104,WBS_CBS!$A$5:$A$16,0)),""))

Sheet Electrical_Estimate
A1: Electrical Estimate
A2: User input layer. Cost_Register must be rebuilt from these sheets via BuildCostRegister.
A4: Item ID | B4: Description | C4: Discipline | D4: WBS | E4: CBS | F4: Cost Category | G4: Cost Type | H4: Quantity | I4: Unit | J4: Unit Rate | K4: Currency | L4: FX Rate | M4: Base Cost | N4: Base Cost EUR | O4: Estimate Basis | P4: Accuracy Low % | Q4: Accuracy High % | R4: Low Cost | S4: Most Likely Cost | T4: High Cost | U4: Contingency Eligible | V4: Escalation Eligible | W4: Spend Category | X4: Phase | Y4: Start Month | Z4: End Month | AA4: Spend Curve | AB4: Notes
A5: EL-001 | B5: MV/LV substation package | C5: =IF($D5="","",IFERROR(INDEX(WBS_CBS!$E$5:$E$16,MATCH($D5,WBS_CBS!$A$5:$A$16,0)),"")) | D5: 7.0 | E5: =IF($D5="","",IFERROR(INDEX(WBS_CBS!$C$5:$C$16,MATCH($D5,WBS_CBS!$A$5:$A$16,0)),"")) | F5: =IF($D5="","",IFERROR(INDEX(WBS_CBS!$J$5:$J$16,MATCH($D5,WBS_CBS!$A$5:$A$16,0)),"")) | G5: Equipment | H5: 1 | I5: lot | J5: 1400000 | K5: EUR | L5: =IF($K5="","",IFERROR(INDEX(FX_Rates!$B$5:$B$14,MATCH($K5,FX_Rates!$A$5:$A$14,0)),"")) | M5: =IF(OR($H5="",$J5=""),"",$H5*$J5) | N5: =IF(OR($M5="",$L5=""),"",$M5*$L5) | O5: Class 3 | P5: =IF($O5="","",IFERROR(INDEX(Basis_of_Estimate!$C$5:$C$9,MATCH($O5,Basis_of_Estimate!$A$5:$A$9,0)),"")) | Q5: =IF($O5="","",IFERROR(INDEX(Basis_of_Estimate!$D$5:$D$9,MATCH($O5,Basis_of_Estimate!$A$5:$A$9,0)),"")) | R5: =IF($N5="","",$N5*(1+$P5)) | S5: =IF($N5="","",$N5) | T5: =IF($N5="","",$N5*(1+$Q5)) | U5: =IF($D5="","",IFERROR(INDEX(WBS_CBS!$M$5:$M$16,MATCH($D5,WBS_CBS!$A$5:$A$16,0)),"Yes")) | V5: =IF($D5="","",IFERROR(INDEX(WBS_CBS!$N$5:$N$16,MATCH($D5,WBS_CBS!$A$5:$A$16,0)),"Yes")) | W5: =IF($D5="","",IFERROR(INDEX(WBS_CBS!$K$5:$K$16,MATCH($D5,WBS_CBS!$A$5:$A$16,0)),"")) | X5: =IF($D5="","",IFERROR(INDEX(WBS_CBS!$F$5:$F$16,MATCH($D5,WBS_CBS!$A$5:$A$16,0)),"")) | Y5: 8 | Z5: 18 | AA5: =IF($D5="","",IFERROR(INDEX(WBS_CBS!$L$5:$L$16,MATCH($D5,WBS_CBS!$A$5:$A$16,0)),""))
A6: EL-002 | B6: MCC and distribution boards | C6: =IF($D6="","",IFERROR(INDEX(WBS_CBS!$E$5:$E$16,MATCH($D6,WBS_CBS!$A$5:$A$16,0)),"")) | D6: 7.0 | E6: =IF($D6="","",IFERROR(INDEX(WBS_CBS!$C$5:$C$16,MATCH($D6,WBS_CBS!$A$5:$A$16,0)),"")) | F6: =IF($D6="","",IFERROR(INDEX(WBS_CBS!$J$5:$J$16,MATCH($D6,WBS_CBS!$A$5:$A$16,0)),"")) | G6: Equipment | H6: 1 | I6: lot | J6: 1200000 | K6: EUR | L6: =IF($K6="","",IFERROR(INDEX(FX_Rates!$B$5:$B$14,MATCH($K6,FX_Rates!$A$5:$A$14,0)),"")) | M6: =IF(OR($H6="",$J6=""),"",$H6*$J6) | N6: =IF(OR($M6="",$L6=""),"",$M6*$L6) | O6: Class 3 | P6: =IF($O6="","",IFERROR(INDEX(Basis_of_Estimate!$C$5:$C$9,MATCH($O6,Basis_of_Estimate!$A$5:$A$9,0)),"")) | Q6: =IF($O6="","",IFERROR(INDEX(Basis_of_Estimate!$D$5:$D$9,MATCH($O6,Basis_of_Estimate!$A$5:$A$9,0)),"")) | R6: =IF($N6="","",$N6*(1+$P6)) | S6: =IF($N6="","",$N6) | T6: =IF($N6="","",$N6*(1+$Q6)) | U6: =IF($D6="","",IFERROR(INDEX(WBS_CBS!$M$5:$M$16,MATCH($D6,WBS_CBS!$A$5:$A$16,0)),"Yes")) | V6: =IF($D6="","",IFERROR(INDEX(WBS_CBS!$N$5:$N$16,MATCH($D6,WBS_CBS!$A$5:$A$16,0)),"Yes")) | W6: =IF($D6="","",IFERROR(INDEX(WBS_CBS!$K$5:$K$16,MATCH($D6,WBS_CBS!$A$5:$A$16,0)),"")) | X6: =IF($D6="","",IFERROR(INDEX(WBS_CBS!$F$5:$F$16,MATCH($D6,WBS_CBS!$A$5:$A$16,0)),"")) | Y6: 9 | Z6: 20 | AA6: =IF($D6="","",IFERROR(INDEX(WBS_CBS!$L$5:$L$16,MATCH($D6,WBS_CBS!$A$5:$A$16,0)),""))
A7: EL-003 | B7: Cable trays, cabling and termination | C7: =IF($D7="","",IFERROR(INDEX(WBS_CBS!$E$5:$E$16,MATCH($D7,WBS_CBS!$A$5:$A$16,0)),"")) | D7: 7.0 | E7: =IF($D7="","",IFERROR(INDEX(WBS_CBS!$C$5:$C$16,MATCH($D7,WBS_CBS!$A$5:$A$16,0)),"")) | F7: =IF($D7="","",IFERROR(INDEX(WBS_CBS!$J$5:$J$16,MATCH($D7,WBS_CBS!$A$5:$A$16,0)),"")) | G7: Bulk Material | H7: 1 | I7: lot | J7: 1600000 | K7: EUR | L7: =IF($K7="","",IFERROR(INDEX(FX_Rates!$B$5:$B$14,MATCH($K7,FX_Rates!$A$5:$A$14,0)),"")) | M7: =IF(OR($H7="",$J7=""),"",$H7*$J7) | N7: =IF(OR($M7="",$L7=""),"",$M7*$L7) | O7: Class 3 | P7: =IF($O7="","",IFERROR(INDEX(Basis_of_Estimate!$C$5:$C$9,MATCH($O7,Basis_of_Estimate!$A$5:$A$9,0)),"")) | Q7: =IF($O7="","",IFERROR(INDEX(Basis_of_Estimate!$D$5:$D$9,MATCH($O7,Basis_of_Estimate!$A$5:$A$9,0)),"")) | R7: =IF($N7="","",$N7*(1+$P7)) | S7: =IF($N7="","",$N7) | T7: =IF($N7="","",$N7*(1+$Q7)) | U7: =IF($D7="","",IFERROR(INDEX(WBS_CBS!$M$5:$M$16,MATCH($D7,WBS_CBS!$A$5:$A$16,0)),"Yes")) | V7: =IF($D7="","",IFERROR(INDEX(WBS_CBS!$N$5:$N$16,MATCH($D7,WBS_CBS!$A$5:$A$16,0)),"Yes")) | W7: =IF($D7="","",IFERROR(INDEX(WBS_CBS!$K$5:$K$16,MATCH($D7,WBS_CBS!$A$5:$A$16,0)),"")) | X7: =IF($D7="","",IFERROR(INDEX(WBS_CBS!$F$5:$F$16,MATCH($D7,WBS_CBS!$A$5:$A$16,0)),"")) | Y7: 15 | Z7: 30 | AA7: =IF($D7="","",IFERROR(INDEX(WBS_CBS!$L$5:$L$16,MATCH($D7,WBS_CBS!$A$5:$A$16,0)),""))
A8: EL-004 | B8: Lighting, earthing and small power | C8: =IF($D8="","",IFERROR(INDEX(WBS_CBS!$E$5:$E$16,MATCH($D8,WBS_CBS!$A$5:$A$16,0)),"")) | D8: 7.0 | E8: =IF($D8="","",IFERROR(INDEX(WBS_CBS!$C$5:$C$16,MATCH($D8,WBS_CBS!$A$5:$A$16,0)),"")) | F8: =IF($D8="","",IFERROR(INDEX(WBS_CBS!$J$5:$J$16,MATCH($D8,WBS_CBS!$A$5:$A$16,0)),"")) | G8: Construction | H8: 1 | I8: lot | J8: 800000 | K8: EUR | L8: =IF($K8="","",IFERROR(INDEX(FX_Rates!$B$5:$B$14,MATCH($K8,FX_Rates!$A$5:$A$14,0)),"")) | M8: =IF(OR($H8="",$J8=""),"",$H8*$J8) | N8: =IF(OR($M8="",$L8=""),"",$M8*$L8) | O8: Class 3 | P8: =IF($O8="","",IFERROR(INDEX(Basis_of_Estimate!$C$5:$C$9,MATCH($O8,Basis_of_Estimate!$A$5:$A$9,0)),"")) | Q8: =IF($O8="","",IFERROR(INDEX(Basis_of_Estimate!$D$5:$D$9,MATCH($O8,Basis_of_Estimate!$A$5:$A$9,0)),"")) | R8: =IF($N8="","",$N8*(1+$P8)) | S8: =IF($N8="","",$N8) | T8: =IF($N8="","",$N8*(1+$Q8)) | U8: =IF($D8="","",IFERROR(INDEX(WBS_CBS!$M$5:$M$16,MATCH($D8,WBS_CBS!$A$5:$A$16,0)),"Yes")) | V8: =IF($D8="","",IFERROR(INDEX(WBS_CBS!$N$5:$N$16,MATCH($D8,WBS_CBS!$A$5:$A$16,0)),"Yes")) | W8: =IF($D8="","",IFERROR(INDEX(WBS_CBS!$K$5:$K$16,MATCH($D8,WBS_CBS!$A$5:$A$16,0)),"")) | X8: =IF($D8="","",IFERROR(INDEX(WBS_CBS!$F$5:$F$16,MATCH($D8,WBS_CBS!$A$5:$A$16,0)),"")) | Y8: 18 | Z8: 31 | AA8: =IF($D8="","",IFERROR(INDEX(WBS_CBS!$L$5:$L$16,MATCH($D8,WBS_CBS!$A$5:$A$16,0)),""))
C9: =IF($D9="","",IFERROR(INDEX(WBS_CBS!$E$5:$E$16,MATCH($D9,WBS_CBS!$A$5:$A$16,0)),"")) | E9: =IF($D9="","",IFERROR(INDEX(WBS_CBS!$C$5:$C$16,MATCH($D9,WBS_CBS!$A$5:$A$16,0)),"")) | F9: =IF($D9="","",IFERROR(INDEX(WBS_CBS!$J$5:$J$16,MATCH($D9,WBS_CBS!$A$5:$A$16,0)),"")) | L9: =IF($K9="","",IFERROR(INDEX(FX_Rates!$B$5:$B$14,MATCH($K9,FX_Rates!$A$5:$A$14,0)),"")) | M9: =IF(OR($H9="",$J9=""),"",$H9*$J9) | N9: =IF(OR($M9="",$L9=""),"",$M9*$L9) | P9: =IF($O9="","",IFERROR(INDEX(Basis_of_Estimate!$C$5:$C$9,MATCH($O9,Basis_of_Estimate!$A$5:$A$9,0)),"")) | Q9: =IF($O9="","",IFERROR(INDEX(Basis_of_Estimate!$D$5:$D$9,MATCH($O9,Basis_of_Estimate!$A$5:$A$9,0)),"")) | R9: =IF($N9="","",$N9*(1+$P9)) | S9: =IF($N9="","",$N9) | T9: =IF($N9="","",$N9*(1+$Q9)) | U9: =IF($D9="","",IFERROR(INDEX(WBS_CBS!$M$5:$M$16,MATCH($D9,WBS_CBS!$A$5:$A$16,0)),"Yes")) | V9: =IF($D9="","",IFERROR(INDEX(WBS_CBS!$N$5:$N$16,MATCH($D9,WBS_CBS!$A$5:$A$16,0)),"Yes")) | W9: =IF($D9="","",IFERROR(INDEX(WBS_CBS!$K$5:$K$16,MATCH($D9,WBS_CBS!$A$5:$A$16,0)),"")) | X9: =IF($D9="","",IFERROR(INDEX(WBS_CBS!$F$5:$F$16,MATCH($D9,WBS_CBS!$A$5:$A$16,0)),"")) | AA9: =IF($D9="","",IFERROR(INDEX(WBS_CBS!$L$5:$L$16,MATCH($D9,WBS_CBS!$A$5:$A$16,0)),""))
C10: =IF($D10="","",IFERROR(INDEX(WBS_CBS!$E$5:$E$16,MATCH($D10,WBS_CBS!$A$5:$A$16,0)),"")) | E10: =IF($D10="","",IFERROR(INDEX(WBS_CBS!$C$5:$C$16,MATCH($D10,WBS_CBS!$A$5:$A$16,0)),"")) | F10: =IF($D10="","",IFERROR(INDEX(WBS_CBS!$J$5:$J$16,MATCH($D10,WBS_CBS!$A$5:$A$16,0)),"")) | L10: =IF($K10="","",IFERROR(INDEX(FX_Rates!$B$5:$B$14,MATCH($K10,FX_Rates!$A$5:$A$14,0)),"")) | M10: =IF(OR($H10="",$J10=""),"",$H10*$J10) | N10: =IF(OR($M10="",$L10=""),"",$M10*$L10) | P10: =IF($O10="","",IFERROR(INDEX(Basis_of_Estimate!$C$5:$C$9,MATCH($O10,Basis_of_Estimate!$A$5:$A$9,0)),"")) | Q10: =IF($O10="","",IFERROR(INDEX(Basis_of_Estimate!$D$5:$D$9,MATCH($O10,Basis_of_Estimate!$A$5:$A$9,0)),"")) | R10: =IF($N10="","",$N10*(1+$P10)) | S10: =IF($N10="","",$N10) | T10: =IF($N10="","",$N10*(1+$Q10)) | U10: =IF($D10="","",IFERROR(INDEX(WBS_CBS!$M$5:$M$16,MATCH($D10,WBS_CBS!$A$5:$A$16,0)),"Yes")) | V10: =IF($D10="","",IFERROR(INDEX(WBS_CBS!$N$5:$N$16,MATCH($D10,WBS_CBS!$A$5:$A$16,0)),"Yes")) | W10: =IF($D10="","",IFERROR(INDEX(WBS_CBS!$K$5:$K$16,MATCH($D10,WBS_CBS!$A$5:$A$16,0)),"")) | X10: =IF($D10="","",IFERROR(INDEX(WBS_CBS!$F$5:$F$16,MATCH($D10,WBS_CBS!$A$5:$A$16,0)),"")) | AA10: =IF($D10="","",IFERROR(INDEX(WBS_CBS!$L$5:$L$16,MATCH($D10,WBS_CBS!$A$5:$A$16,0)),""))
C11: =IF($D11="","",IFERROR(INDEX(WBS_CBS!$E$5:$E$16,MATCH($D11,WBS_CBS!$A$5:$A$16,0)),"")) | E11: =IF($D11="","",IFERROR(INDEX(WBS_CBS!$C$5:$C$16,MATCH($D11,WBS_CBS!$A$5:$A$16,0)),"")) | F11: =IF($D11="","",IFERROR(INDEX(WBS_CBS!$J$5:$J$16,MATCH($D11,WBS_CBS!$A$5:$A$16,0)),"")) | L11: =IF($K11="","",IFERROR(INDEX(FX_Rates!$B$5:$B$14,MATCH($K11,FX_Rates!$A$5:$A$14,0)),"")) | M11: =IF(OR($H11="",$J11=""),"",$H11*$J11) | N11: =IF(OR($M11="",$L11=""),"",$M11*$L11) | P11: =IF($O11="","",IFERROR(INDEX(Basis_of_Estimate!$C$5:$C$9,MATCH($O11,Basis_of_Estimate!$A$5:$A$9,0)),"")) | Q11: =IF($O11="","",IFERROR(INDEX(Basis_of_Estimate!$D$5:$D$9,MATCH($O11,Basis_of_Estimate!$A$5:$A$9,0)),"")) | R11: =IF($N11="","",$N11*(1+$P11)) | S11: =IF($N11="","",$N11) | T11: =IF($N11="","",$N11*(1+$Q11)) | U11: =IF($D11="","",IFERROR(INDEX(WBS_CBS!$M$5:$M$16,MATCH($D11,WBS_CBS!$A$5:$A$16,0)),"Yes")) | V11: =IF($D11="","",IFERROR(INDEX(WBS_CBS!$N$5:$N$16,MATCH($D11,WBS_CBS!$A$5:$A$16,0)),"Yes")) | W11: =IF($D11="","",IFERROR(INDEX(WBS_CBS!$K$5:$K$16,MATCH($D11,WBS_CBS!$A$5:$A$16,0)),"")) | X11: =IF($D11="","",IFERROR(INDEX(WBS_CBS!$F$5:$F$16,MATCH($D11,WBS_CBS!$A$5:$A$16,0)),"")) | AA11: =IF($D11="","",IFERROR(INDEX(WBS_CBS!$L$5:$L$16,MATCH($D11,WBS_CBS!$A$5:$A$16,0)),""))
C12: =IF($D12="","",IFERROR(INDEX(WBS_CBS!$E$5:$E$16,MATCH($D12,WBS_CBS!$A$5:$A$16,0)),"")) | E12: =IF($D12="","",IFERROR(INDEX(WBS_CBS!$C$5:$C$16,MATCH($D12,WBS_CBS!$A$5:$A$16,0)),"")) | F12: =IF($D12="","",IFERROR(INDEX(WBS_CBS!$J$5:$J$16,MATCH($D12,WBS_CBS!$A$5:$A$16,0)),"")) | L12: =IF($K12="","",IFERROR(INDEX(FX_Rates!$B$5:$B$14,MATCH($K12,FX_Rates!$A$5:$A$14,0)),"")) | M12: =IF(OR($H12="",$J12=""),"",$H12*$J12) | N12: =IF(OR($M12="",$L12=""),"",$M12*$L12) | P12: =IF($O12="","",IFERROR(INDEX(Basis_of_Estimate!$C$5:$C$9,MATCH($O12,Basis_of_Estimate!$A$5:$A$9,0)),"")) | Q12: =IF($O12="","",IFERROR(INDEX(Basis_of_Estimate!$D$5:$D$9,MATCH($O12,Basis_of_Estimate!$A$5:$A$9,0)),"")) | R12: =IF($N12="","",$N12*(1+$P12)) | S12: =IF($N12="","",$N12) | T12: =IF($N12="","",$N12*(1+$Q12)) | U12: =IF($D12="","",IFERROR(INDEX(WBS_CBS!$M$5:$M$16,MATCH($D12,WBS_CBS!$A$5:$A$16,0)),"Yes")) | V12: =IF($D12="","",IFERROR(INDEX(WBS_CBS!$N$5:$N$16,MATCH($D12,WBS_CBS!$A$5:$A$16,0)),"Yes")) | W12: =IF($D12="","",IFERROR(INDEX(WBS_CBS!$K$5:$K$16,MATCH($D12,WBS_CBS!$A$5:$A$16,0)),"")) | X12: =IF($D12="","",IFERROR(INDEX(WBS_CBS!$F$5:$F$16,MATCH($D12,WBS_CBS!$A$5:$A$16,0)),"")) | AA12: =IF($D12="","",IFERROR(INDEX(WBS_CBS!$L$5:$L$16,MATCH($D12,WBS_CBS!$A$5:$A$16,0)),""))
C13: =IF($D13="","",IFERROR(INDEX(WBS_CBS!$E$5:$E$16,MATCH($D13,WBS_CBS!$A$5:$A$16,0)),"")) | E13: =IF($D13="","",IFERROR(INDEX(WBS_CBS!$C$5:$C$16,MATCH($D13,WBS_CBS!$A$5:$A$16,0)),"")) | F13: =IF($D13="","",IFERROR(INDEX(WBS_CBS!$J$5:$J$16,MATCH($D13,WBS_CBS!$A$5:$A$16,0)),"")) | L13: =IF($K13="","",IFERROR(INDEX(FX_Rates!$B$5:$B$14,MATCH($K13,FX_Rates!$A$5:$A$14,0)),"")) | M13: =IF(OR($H13="",$J13=""),"",$H13*$J13) | N13: =IF(OR($M13="",$L13=""),"",$M13*$L13) | P13: =IF($O13="","",IFERROR(INDEX(Basis_of_Estimate!$C$5:$C$9,MATCH($O13,Basis_of_Estimate!$A$5:$A$9,0)),"")) | Q13: =IF($O13="","",IFERROR(INDEX(Basis_of_Estimate!$D$5:$D$9,MATCH($O13,Basis_of_Estimate!$A$5:$A$9,0)),"")) | R13: =IF($N13="","",$N13*(1+$P13)) | S13: =IF($N13="","",$N13) | T13: =IF($N13="","",$N13*(1+$Q13)) | U13: =IF($D13="","",IFERROR(INDEX(WBS_CBS!$M$5:$M$16,MATCH($D13,WBS_CBS!$A$5:$A$16,0)),"Yes")) | V13: =IF($D13="","",IFERROR(INDEX(WBS_CBS!$N$5:$N$16,MATCH($D13,WBS_CBS!$A$5:$A$16,0)),"Yes")) | W13: =IF($D13="","",IFERROR(INDEX(WBS_CBS!$K$5:$K$16,MATCH($D13,WBS_CBS!$A$5:$A$16,0)),"")) | X13: =IF($D13="","",IFERROR(INDEX(WBS_CBS!$F$5:$F$16,MATCH($D13,WBS_CBS!$A$5:$A$16,0)),"")) | AA13: =IF($D13="","",IFERROR(INDEX(WBS_CBS!$L$5:$L$16,MATCH($D13,WBS_CBS!$A$5:$A$16,0)),""))
C14: =IF($D14="","",IFERROR(INDEX(WBS_CBS!$E$5:$E$16,MATCH($D14,WBS_CBS!$A$5:$A$16,0)),"")) | E14: =IF($D14="","",IFERROR(INDEX(WBS_CBS!$C$5:$C$16,MATCH($D14,WBS_CBS!$A$5:$A$16,0)),"")) | F14: =IF($D14="","",IFERROR(INDEX(WBS_CBS!$J$5:$J$16,MATCH($D14,WBS_CBS!$A$5:$A$16,0)),"")) | L14: =IF($K14="","",IFERROR(INDEX(FX_Rates!$B$5:$B$14,MATCH($K14,FX_Rates!$A$5:$A$14,0)),"")) | M14: =IF(OR($H14="",$J14=""),"",$H14*$J14) | N14: =IF(OR($M14="",$L14=""),"",$M14*$L14) | P14: =IF($O14="","",IFERROR(INDEX(Basis_of_Estimate!$C$5:$C$9,MATCH($O14,Basis_of_Estimate!$A$5:$A$9,0)),"")) | Q14: =IF($O14="","",IFERROR(INDEX(Basis_of_Estimate!$D$5:$D$9,MATCH($O14,Basis_of_Estimate!$A$5:$A$9,0)),"")) | R14: =IF($N14="","",$N14*(1+$P14)) | S14: =IF($N14="","",$N14) | T14: =IF($N14="","",$N14*(1+$Q14)) | U14: =IF($D14="","",IFERROR(INDEX(WBS_CBS!$M$5:$M$16,MATCH($D14,WBS_CBS!$A$5:$A$16,0)),"Yes")) | V14: =IF($D14="","",IFERROR(INDEX(WBS_CBS!$N$5:$N$16,MATCH($D14,WBS_CBS!$A$5:$A$16,0)),"Yes")) | W14: =IF($D14="","",IFERROR(INDEX(WBS_CBS!$K$5:$K$16,MATCH($D14,WBS_CBS!$A$5:$A$16,0)),"")) | X14: =IF($D14="","",IFERROR(INDEX(WBS_CBS!$F$5:$F$16,MATCH($D14,WBS_CBS!$A$5:$A$16,0)),"")) | AA14: =IF($D14="","",IFERROR(INDEX(WBS_CBS!$L$5:$L$16,MATCH($D14,WBS_CBS!$A$5:$A$16,0)),""))
C15: =IF($D15="","",IFERROR(INDEX(WBS_CBS!$E$5:$E$16,MATCH($D15,WBS_CBS!$A$5:$A$16,0)),"")) | E15: =IF($D15="","",IFERROR(INDEX(WBS_CBS!$C$5:$C$16,MATCH($D15,WBS_CBS!$A$5:$A$16,0)),"")) | F15: =IF($D15="","",IFERROR(INDEX(WBS_CBS!$J$5:$J$16,MATCH($D15,WBS_CBS!$A$5:$A$16,0)),"")) | L15: =IF($K15="","",IFERROR(INDEX(FX_Rates!$B$5:$B$14,MATCH($K15,FX_Rates!$A$5:$A$14,0)),"")) | M15: =IF(OR($H15="",$J15=""),"",$H15*$J15) | N15: =IF(OR($M15="",$L15=""),"",$M15*$L15) | P15: =IF($O15="","",IFERROR(INDEX(Basis_of_Estimate!$C$5:$C$9,MATCH($O15,Basis_of_Estimate!$A$5:$A$9,0)),"")) | Q15: =IF($O15="","",IFERROR(INDEX(Basis_of_Estimate!$D$5:$D$9,MATCH($O15,Basis_of_Estimate!$A$5:$A$9,0)),"")) | R15: =IF($N15="","",$N15*(1+$P15)) | S15: =IF($N15="","",$N15) | T15: =IF($N15="","",$N15*(1+$Q15)) | U15: =IF($D15="","",IFERROR(INDEX(WBS_CBS!$M$5:$M$16,MATCH($D15,WBS_CBS!$A$5:$A$16,0)),"Yes")) | V15: =IF($D15="","",IFERROR(INDEX(WBS_CBS!$N$5:$N$16,MATCH($D15,WBS_CBS!$A$5:$A$16,0)),"Yes")) | W15: =IF($D15="","",IFERROR(INDEX(WBS_CBS!$K$5:$K$16,MATCH($D15,WBS_CBS!$A$5:$A$16,0)),"")) | X15: =IF($D15="","",IFERROR(INDEX(WBS_CBS!$F$5:$F$16,MATCH($D15,WBS_CBS!$A$5:$A$16,0)),"")) | AA15: =IF($D15="","",IFERROR(INDEX(WBS_CBS!$L$5:$L$16,MATCH($D15,WBS_CBS!$A$5:$A$16,0)),""))
C16: =IF($D16="","",IFERROR(INDEX(WBS_CBS!$E$5:$E$16,MATCH($D16,WBS_CBS!$A$5:$A$16,0)),"")) | E16: =IF($D16="","",IFERROR(INDEX(WBS_CBS!$C$5:$C$16,MATCH($D16,WBS_CBS!$A$5:$A$16,0)),"")) | F16: =IF($D16="","",IFERROR(INDEX(WBS_CBS!$J$5:$J$16,MATCH($D16,WBS_CBS!$A$5:$A$16,0)),"")) | L16: =IF($K16="","",IFERROR(INDEX(FX_Rates!$B$5:$B$14,MATCH($K16,FX_Rates!$A$5:$A$14,0)),"")) | M16: =IF(OR($H16="",$J16=""),"",$H16*$J16) | N16: =IF(OR($M16="",$L16=""),"",$M16*$L16) | P16: =IF($O16="","",IFERROR(INDEX(Basis_of_Estimate!$C$5:$C$9,MATCH($O16,Basis_of_Estimate!$A$5:$A$9,0)),"")) | Q16: =IF($O16="","",IFERROR(INDEX(Basis_of_Estimate!$D$5:$D$9,MATCH($O16,Basis_of_Estimate!$A$5:$A$9,0)),"")) | R16: =IF($N16="","",$N16*(1+$P16)) | S16: =IF($N16="","",$N16) | T16: =IF($N16="","",$N16*(1+$Q16)) | U16: =IF($D16="","",IFERROR(INDEX(WBS_CBS!$M$5:$M$16,MATCH($D16,WBS_CBS!$A$5:$A$16,0)),"Yes")) | V16: =IF($D16="","",IFERROR(INDEX(WBS_CBS!$N$5:$N$16,MATCH($D16,WBS_CBS!$A$5:$A$16,0)),"Yes")) | W16: =IF($D16="","",IFERROR(INDEX(WBS_CBS!$K$5:$K$16,MATCH($D16,WBS_CBS!$A$5:$A$16,0)),"")) | X16: =IF($D16="","",IFERROR(INDEX(WBS_CBS!$F$5:$F$16,MATCH($D16,WBS_CBS!$A$5:$A$16,0)),"")) | AA16: =IF($D16="","",IFERROR(INDEX(WBS_CBS!$L$5:$L$16,MATCH($D16,WBS_CBS!$A$5:$A$16,0)),""))
C17: =IF($D17="","",IFERROR(INDEX(WBS_CBS!$E$5:$E$16,MATCH($D17,WBS_CBS!$A$5:$A$16,0)),"")) | E17: =IF($D17="","",IFERROR(INDEX(WBS_CBS!$C$5:$C$16,MATCH($D17,WBS_CBS!$A$5:$A$16,0)),"")) | F17: =IF($D17="","",IFERROR(INDEX(WBS_CBS!$J$5:$J$16,MATCH($D17,WBS_CBS!$A$5:$A$16,0)),"")) | L17: =IF($K17="","",IFERROR(INDEX(FX_Rates!$B$5:$B$14,MATCH($K17,FX_Rates!$A$5:$A$14,0)),"")) | M17: =IF(OR($H17="",$J17=""),"",$H17*$J17) | N17: =IF(OR($M17="",$L17=""),"",$M17*$L17) | P17: =IF($O17="","",IFERROR(INDEX(Basis_of_Estimate!$C$5:$C$9,MATCH($O17,Basis_of_Estimate!$A$5:$A$9,0)),"")) | Q17: =IF($O17="","",IFERROR(INDEX(Basis_of_Estimate!$D$5:$D$9,MATCH($O17,Basis_of_Estimate!$A$5:$A$9,0)),"")) | R17: =IF($N17="","",$N17*(1+$P17)) | S17: =IF($N17="","",$N17) | T17: =IF($N17="","",$N17*(1+$Q17)) | U17: =IF($D17="","",IFERROR(INDEX(WBS_CBS!$M$5:$M$16,MATCH($D17,WBS_CBS!$A$5:$A$16,0)),"Yes")) | V17: =IF($D17="","",IFERROR(INDEX(WBS_CBS!$N$5:$N$16,MATCH($D17,WBS_CBS!$A$5:$A$16,0)),"Yes")) | W17: =IF($D17="","",IFERROR(INDEX(WBS_CBS!$K$5:$K$16,MATCH($D17,WBS_CBS!$A$5:$A$16,0)),"")) | X17: =IF($D17="","",IFERROR(INDEX(WBS_CBS!$F$5:$F$16,MATCH($D17,WBS_CBS!$A$5:$A$16,0)),"")) | AA17: =IF($D17="","",IFERROR(INDEX(WBS_CBS!$L$5:$L$16,MATCH($D17,WBS_CBS!$A$5:$A$16,0)),""))
